Workbook

Sheet 📊 DASHBOARD
A1: 🕉 SRI PONNIAMMAN TEMPLE — ANNUAL ACCOUNTS 🕉
A2: Multi-Year Dashboard — Select Year to View Annual Summary
A4: 📅 SELECT YEAR
A5: Select Year ▼ | D5: 2026
A7: 📊 FINANCIAL SUMMARY
A8: ANNUAL BUDGET (₹) | D8: {=IFERROR(INDIRECT($D$5&"!D9"),0)} -> 177000
A9: DONATIONS PLEDGED (₹) | D9: {=IFERROR(INDIRECT($D$5&"!D10"),0)} -> 307803
A10: RECEIVED (₹) | D10: {=IFERROR(INDIRECT($D$5&"!D11"),0)} -> 247803
A11: PENDING (₹) | D11: {=IFERROR(INDIRECT($D$5&"!D12"),0)} -> 60000
A12: IN-KIND DONATIONS (₹) | D12: {=IFERROR(INDIRECT($D$5&"!D13"),0)} -> 8400
A13: TOTAL EXPENSES (₹) | D13: {=IFERROR(INDIRECT($D$5&"!D14"),0)} -> 147622
A14: NET SURPLUS / (DEFICIT) (₹) | D14: {=IFERROR(INDIRECT($D$5&"!D15"),0)} -> 29378
A15: TOTAL DONORS | D15: {=IFERROR(INDIRECT($D$5&"!D16"),0)} -> 47
A17: 💰 EXPENSE CATEGORY BREAKDOWN
A18: # | B18: Category | D18: Budget (₹) | E18: Actual (₹) | F18: Balance (₹)
A19: 1 | B19: Puja & Rituals | D19: {=IFERROR(INDIRECT($D$5&"!D20"),0)} -> 52000 | E19: {=IFERROR(INDIRECT($D$5&"!E20"),0)} -> 16502 | F19: =D19-E19 -> 35498
A20: 2 | B20: Decorations & Flowers | D20: {=IFERROR(INDIRECT($D$5&"!D21"),0)} -> 32500 | E20: {=IFERROR(INDIRECT($D$5&"!E21"),0)} -> 7002 | F20: =D20-E20 -> 25498
A21: 3 | B21: Food & Catering | D21: {=IFERROR(INDIRECT($D$5&"!D22"),0)} -> 45000 | E21: {=IFERROR(INDIRECT($D$5&"!E22"),0)} -> 40000 | F21: =D21-E21 -> 5000
A22: 4 | B22: Infrastructure & Logistics | D22: {=IFERROR(INDIRECT($D$5&"!D23"),0)} -> 28500 | E22: {=IFERROR(INDIRECT($D$5&"!E23"),0)} -> 4787 | F22: =D22-E22 -> 23713
A23: 5 | B23: Miscellaneous | D23: {=IFERROR(INDIRECT($D$5&"!D24"),0)} -> 19000 | E23: {=IFERROR(INDIRECT($D$5&"!E24"),0)} -> 2961 | F23: =D23-E23 -> 16039
A24: 6 | B24: Materials | D24: {=IFERROR(INDIRECT($D$5&"!D25"),0)} -> 0 | E24: {=IFERROR(INDIRECT($D$5&"!E25"),0)} -> 63850 | F24: =D24-E24 -> -63850
A25: 7 | B25: Labour | D25: {=IFERROR(INDIRECT($D$5&"!D26"),0)} -> 0 | E25: {=IFERROR(INDIRECT($D$5&"!E26"),0)} -> 10000 | F25: =D25-E25 -> -10000
A26: 8 | B26: Transport | D26: {=IFERROR(INDIRECT($D$5&"!D27"),0)} -> 0 | E26: {=IFERROR(INDIRECT($D$5&"!E27"),0)} -> 1600 | F26: =D26-E26 -> -1600
A27: 9 | B27: Food | D27: {=IFERROR(INDIRECT($D$5&"!D28"),0)} -> 0 | E27: {=IFERROR(INDIRECT($D$5&"!E28"),0)} -> 920 | F27: =D27-E27 -> -920
A28: TOTAL | D28: =SUM(D19:D27) -> 177000 | E28: =SUM(E19:E27) -> 147622 | F28: =D28-E28 -> 29378
A30: 🗂️ EXPENSE TYPE SUMMARY
A31: Expense Type | D31: Total Amount (₹)
A32: Aadi Festival | D32: {=IFERROR(INDIRECT($D$5&"!D33"),0)} -> 70852
A33: Temple Development | D33: {=IFERROR(INDIRECT($D$5&"!D34"),0)} -> 76770
A34: Temple Operations | D34: {=IFERROR(INDIRECT($D$5&"!D35"),0)} -> 0
A35: Others | D35: {=IFERROR(INDIRECT($D$5&"!D36"),0)} -> 0
A36: TOTAL | D36: =SUM(D32:D35) -> 147622
A38: 💝 DONATION TYPE SUMMARY
A39: Donation Type | D39: Pledged (₹) | E39: Received (₹) | F39: Pending (₹)
A40: Aadi Festival | D40: {=IFERROR(INDIRECT($D$5&"!D75"),0)} -> 204603 | E40: {=IFERROR(INDIRECT($D$5&"!E75"),0)} -> 149603 | F40: =D40-E40 -> 55000
A41: Temple Development | D41: {=IFERROR(INDIRECT($D$5&"!D76"),0)} -> 88500 | E41: {=IFERROR(INDIRECT($D$5&"!E76"),0)} -> 83500 | F41: =D41-E41 -> 5000
A42: Birthday Pooja | D42: {=IFERROR(INDIRECT($D$5&"!D77"),0)} -> 800 | E42: {=IFERROR(INDIRECT($D$5&"!E77"),0)} -> 800 | F42: =D42-E42 -> 0
A43: Anniversary Pooja | D43: {=IFERROR(INDIRECT($D$5&"!D78"),0)} -> 0 | E43: {=IFERROR(INDIRECT($D$5&"!E78"),0)} -> 0 | F43: =D43-E43 -> 0
A44: Pournami Pooja | D44: {=IFERROR(INDIRECT($D$5&"!D79"),0)} -> 0 | E44: {=IFERROR(INDIRECT($D$5&"!E79"),0)} -> 0 | F44: =D44-E44 -> 0
A45: Amavasai Pooja | D45: {=IFERROR(INDIRECT($D$5&"!D80"),0)} -> 0 | E45: {=IFERROR(INDIRECT($D$5&"!E80"),0)} -> 0 | F45: =D45-E45 -> 0
...

Sheet 📈 CUMULATIVE
A1: 🕉 SRI PONNIAMMAN TEMPLE — ANNUAL ACCOUNTS SUMMARY 🕉
A2: Year-on-year financial overview across all festivals
A4: 📈 YEAR-WISE COLLECTION SUMMARY
B5: Year | C5: Festival Date | D5: Budget (₹) | E5: Pledged (₹) | F5: Received (₹) | G5: Pending (₹) | H5: Expenses (₹) | I5: Net Surplus/(Deficit) (₹)
B6: 2026 | C6: 16-Aug-2026 | D6: =IFERROR('2026'!D9,0) -> 177000 | E6: =IFERROR('2026'!D10,0) -> 307803 | F6: =IFERROR('2026'!D11,0) -> 247803 | G6: =IFERROR('2026'!D12,0) -> 60000 | H6: =IFERROR('2026'!D14,0) -> 147622 | I6: =IFERROR('2026'!D15,0) -> 29378
B7: 2027 | C7: — | D7: =IFERROR('2027'!D9,0) -> 0 | E7: =IFERROR('2027'!D10,0) -> 0 | F7: =IFERROR('2027'!D11,0) -> 0 | G7: =IFERROR('2027'!D12,0) -> 0 | H7: =IFERROR('2027'!D14,0) -> 0 | I7: =IFERROR('2027'!D15,0) -> 0
A8: CUMULATIVE TOTAL | D8: =SUM(D6:D7) -> 177000 | E8: =SUM(E6:E7) -> 307803 | F8: =SUM(F6:F7) -> 247803 | G8: =SUM(G6:G7) -> 60000 | H8: =SUM(H6:H7) -> 147622 | I8: =SUM(I6:I7) -> 29378
A10: 🗂️ EXPENSE TYPE — YEAR COMPARISON
A11: Expense Type | B11: 2026 | C11: 2027
A12: Aadi Festival | B12: =IFERROR('2026'!D33,0) -> 70852 | C12: =IFERROR('2027'!D33,0) -> 0
A13: Temple Development | B13: =IFERROR('2026'!D34,0) -> 76770 | C13: =IFERROR('2027'!D34,0) -> 0
A14: Temple Operations | B14: =IFERROR('2026'!D35,0) -> 0 | C14: =IFERROR('2027'!D35,0) -> 0
A15: Others | B15: =IFERROR('2026'!D36,0) -> 0 | C15: =IFERROR('2027'!D36,0) -> 0
A16: TOTAL | B16: =SUM(B12:B15) -> 147622 | C16: =SUM(C12:C15) -> 0

Sheet 2026
A1: 🕉 SRI PONNIAMMAN TEMPLE — ANNUAL ACCOUNTS 2026 🕉
A2: Financial Year: 2026 | Live data via Google Sheets IMPORTRANGE
A4: 🎪 FESTIVALS / EVENTS IN THIS YEAR
A5: # | B5: Festival / Event | D5: Date | E5: Notes / Description
A6: 1
A8: 📊 ANNUAL SUMMARY
A9: Annual Budget (₹) | D9: =SUM(D20:D28) -> 177000
A10: Total Donations Pledged (₹) | D10: =IFERROR(__xludf.DUMMYFUNCTION("IFERROR(INDEX(QUERY(IMPORTRANGE(""12PgU-zwv8gBrFfxvJpoPIPcxUHWup-vsxMH3HWUigZ8"",""💰 Donations!A4:D200""),""SELECT SUM(Col3) WHERE Col1 LIKE '2026/D/%' LABEL SUM(Col3) ''""),1),0)"),307803.0) -> 307803
A11: Donations Received (₹) | D11: =IFERROR(__xludf.DUMMYFUNCTION("IFERROR(INDEX(QUERY(IMPORTRANGE(""12PgU-zwv8gBrFfxvJpoPIPcxUHWup-vsxMH3HWUigZ8"",""💰 Donations!A4:D200""),""SELECT SUM(Col4) WHERE Col1 LIKE '2026/D/%' LABEL SUM(Col4) ''""),1),0)"),247803.0) -> 247803
A12: Donations Pending (₹) | D12: =D10-D11 -> 60000
A13: In-Kind Donations (₹) | D13: =IFERROR(__xludf.DUMMYFUNCTION("IFERROR(INDEX(QUERY(IMPORTRANGE(""12PgU-zwv8gBrFfxvJpoPIPcxUHWup-vsxMH3HWUigZ8"",""🌿 In-Kind!A4:E200""),""SELECT SUM(Col5) WHERE Col1 LIKE '2026/IK/%' LABEL SUM(Col5) ''""),1),0)"),8400.0) -> 8400
A14: Total Expenses (₹) | D14: =IFERROR(__xludf.DUMMYFUNCTION("IFERROR(INDEX(QUERY(IMPORTRANGE(""12PgU-zwv8gBrFfxvJpoPIPcxUHWup-vsxMH3HWUigZ8"",""💸 Expenses!A5:F200""),""SELECT SUM(Col6) WHERE Col1 LIKE '2026/EX/%' LABEL SUM(Col6) ''""),1),0)"),147622.0) -> 147622
A15: Net Surplus / (Deficit) (₹) | D15: =D9-D14 -> 29378
A16: Total Donors | D16: =IFERROR(__xludf.DUMMYFUNCTION("IFERROR(INDEX(QUERY(IMPORTRANGE(""12PgU-zwv8gBrFfxvJpoPIPcxUHWup-vsxMH3HWUigZ8"",""💰 Donations!A4:D200""),""SELECT COUNT(Col1) WHERE Col1 LIKE '2026/D/%' LABEL COUNT(Col1) ''""),1),0)"),47.0) -> 47
A18: 💰 EXPENSE CATEGORY BREAKDOWN (Budget vs Actual)
A19: # | B19: Category | C19: Group | D19: Budget (₹) | E19: Actual (₹) | F19: Balance (₹)
A20: 1 | B20: Puja & Rituals | C20: Aadi Festival | D20: =IFERROR(__xludf.DUMMYFUNCTION("IFERROR(INDEX(QUERY(IMPORTRANGE(""12PgU-zwv8gBrFfxvJpoPIPcxUHWup-vsxMH3HWUigZ8"",""💰 Budget!C5:E200""),""SELECT SUM(Col3) WHERE Col1='Puja & Rituals' LABEL SUM(Col3) ''""),1),0)"),52000.0) -> 52000 | E20: =IFERROR(__xludf.DUMMYFUNCTION("IFERROR(INDEX(QUERY(IMPORTRANGE(""12PgU-zwv8gBrFfxvJpoPIPcxUHWup-vsxMH3HWUigZ8"",""💸 Expenses!E5:F200""),""SELECT SUM(Col2) WHERE Col1='Puja & Rituals' LABEL SUM(Col2) ''""),1),0)"),16502.0) -> 16502 | F20: =D20-E20 -> 35498
A21: 2 | B21: Decorations & Flowers | C21: Aadi Festival | D21: =IFERROR(__xludf.DUMMYFUNCTION("IFERROR(INDEX(QUERY(IMPORTRANGE(""12PgU-zwv8gBrFfxvJpoPIPcxUHWup-vsxMH3HWUigZ8"",""💰 Budget!C5:E200""),""SELECT SUM(Col3) WHERE Col1='Decorations & Flowers' LABEL SUM(Col3) ''""),1),0)"),32500.0) -> 32500 | E21: =IFERROR(__xludf.DUMMYFUNCTION("IFERROR(INDEX(QUERY(IMPORTRANGE(""12PgU-zwv8gBrFfxvJpoPIPcxUHWup-vsxMH3HWUigZ8"",""💸 Expenses!E5:F200""),""SELECT SUM(Col2) WHERE Col1='Decorations & Flowers' LABEL SUM(Col2) ''""),1),0)"),7002.0) -> 7002 | F21: =D21-E21 -> 25498
A22: 3 | B22: Food & Catering | C22: Aadi Festival | D22: =IFERROR(__xludf.DUMMYFUNCTION("IFERROR(INDEX(QUERY(IMPORTRANGE(""12PgU-zwv8gBrFfxvJpoPIPcxUHWup-vsxMH3HWUigZ8"",""💰 Budget!C5:E200""),""SELECT SUM(Col3) WHERE Col1='Food & Catering' LABEL SUM(Col3) ''""),1),0)"),45000.0) -> 45000 | E22: =IFERROR(__xludf.DUMMYFUNCTION("IFERROR(INDEX(QUERY(IMPORTRANGE(""12PgU-zwv8gBrFfxvJpoPIPcxUHWup-vsxMH3HWUigZ8"",""💸 Expenses!E5:F200""),""SELECT SUM(Col2) WHERE Col1='Food & Catering' LABEL SUM(Col2) ''""),1),0)"),40000.0) -> 40000 | F22: =D22-E22 -> 5000
A23: 4 | B23: Infrastructure & Logistics | C23: Aadi Festival | D23: =IFERROR(__xludf.DUMMYFUNCTION("IFERROR(INDEX(QUERY(IMPORTRANGE(""12PgU-zwv8gBrFfxvJpoPIPcxUHWup-vsxMH3HWUigZ8"",""💰 Budget!C5:E200""),""SELECT SUM(Col3) WHERE Col1='Infrastructure & Logistics' LABEL SUM(Col3) ''""),1),0)"),28500.0) -> 28500 | E23: =IFERROR(__xludf.DUMMYFUNCTION("IFERROR(INDEX(QUERY(IMPORTRANGE(""12PgU-zwv8gBrFfxvJpoPIPcxUHWup-vsxMH3HWUigZ8"",""💸 Expenses!E5:F200""),""SELECT SUM(Col2) WHERE Col1='Infrastructure & Logistics' LABEL SUM(Col2) ''""),1),0)"),4787.0) -> 4787 | F23: =D23-E23 -> 23713
A24: 5 | B24: Miscellaneous | C24: Aadi Festival | D24: =IFERROR(__xludf.DUMMYFUNCTION("IFERROR(INDEX(QUERY(IMPORTRANGE(""12PgU-zwv8gBrFfxvJpoPIPcxUHWup-vsxMH3HWUigZ8"",""💰 Budget!C5:E200""),""SELECT SUM(Col3) WHERE Col1='Miscellaneous' LABEL SUM(Col3) ''""),1),0)"),19000.0) -> 19000 | E24: =IFERROR(__xludf.DUMMYFUNCTION("IFERROR(INDEX(QUERY(IMPORTRANGE(""12PgU-zwv8gBrFfxvJpoPIPcxUHWup-vsxMH3HWUigZ8"",""💸 Expenses!E5:F200""),""SELECT SUM(Col2) WHERE Col1='Miscellaneous' LABEL SUM(Col2) ''""),1),0)"),2961.0) -> 2961 | F24: =D24-E24 -> 16039
A25: 6 | B25: Materials | C25: Temple Development | D25: =IFERROR(__xludf.DUMMYFUNCTION("IFERROR(INDEX(QUERY(IMPORTRANGE(""12PgU-zwv8gBrFfxvJpoPIPcxUHWup-vsxMH3HWUigZ8"",""💰 Budget!C5:E200""),""SELECT SUM(Col3) WHERE Col1='Materials' LABEL SUM(Col3) ''""),1),0)"),0.0) -> 0 | E25: =IFERROR(__xludf.DUMMYFUNCTION("IFERROR(INDEX(QUERY(IMPORTRANGE(""12PgU-zwv8gBrFfxvJpoPIPcxUHWup-vsxMH3HWUigZ8"",""💸 Expenses!E5:F200""),""SELECT SUM(Col2) WHERE Col1='Materials' LABEL SUM(Col2) ''""),1),0)"),63850.0) -> 63850 | F25: =D25-E25 -> -63850
A26: 7 | B26: Labour | C26: Temple Development | D26: =IFERROR(__xludf.DUMMYFUNCTION("IFERROR(INDEX(QUERY(IMPORTRANGE(""12PgU-zwv8gBrFfxvJpoPIPcxUHWup-vsxMH3HWUigZ8"",""💰 Budget!C5:E200""),""SELECT SUM(Col3) WHERE Col1='Labour' LABEL SUM(Col3) ''""),1),0)"),0.0) -> 0 | E26: =IFERROR(__xludf.DUMMYFUNCTION("IFERROR(INDEX(QUERY(IMPORTRANGE(""12PgU-zwv8gBrFfxvJpoPIPcxUHWup-vsxMH3HWUigZ8"",""💸 Expenses!E5:F200""),""SELECT SUM(Col2) WHERE Col1='Labour' LABEL SUM(Col2) ''""),1),0)"),10000.0) -> 10000 | F26: =D26-E26 -> -10000
A27: 8 | B27: Transport | C27: Temple Development | D27: =IFERROR(__xludf.DUMMYFUNCTION("IFERROR(INDEX(QUERY(IMPORTRANGE(""12PgU-zwv8gBrFfxvJpoPIPcxUHWup-vsxMH3HWUigZ8"",""💰 Budget!C5:E200""),""SELECT SUM(Col3) WHERE Col1='Transport' LABEL SUM(Col3) ''""),1),0)"),0.0) -> 0 | E27: =IFERROR(__xludf.DUMMYFUNCTION("IFERROR(INDEX(QUERY(IMPORTRANGE(""12PgU-zwv8gBrFfxvJpoPIPcxUHWup-vsxMH3HWUigZ8"",""💸 Expenses!E5:F200""),""SELECT SUM(Col2) WHERE Col1='Transport' LABEL SUM(Col2) ''""),1),0)"),1600.0) -> 1600 | F27: =D27-E27 -> -1600
A28: 9 | B28: Food | C28: Temple Development | D28: =IFERROR(__xludf.DUMMYFUNCTION("IFERROR(INDEX(QUERY(IMPORTRANGE(""12PgU-zwv8gBrFfxvJpoPIPcxUHWup-vsxMH3HWUigZ8"",""💰 Budget!C5:E200""),""SELECT SUM(Col3) WHERE Col1='Food' LABEL SUM(Col3) ''""),1),0)"),0.0) -> 0 | E28: =IFERROR(__xludf.DUMMYFUNCTION("IFERROR(INDEX(QUERY(IMPORTRANGE(""12PgU-zwv8gBrFfxvJpoPIPcxUHWup-vsxMH3HWUigZ8"",""💸 Expenses!E5:F200""),""SELECT SUM(Col2) WHERE Col1='Food' LABEL SUM(Col2) ''""),1),0)"),920.0) -> 920 | F28: =D28-E28 -> -920
A29: TOTAL ALL CATEGORIES | D29: =SUM(D20:D28) -> 177000 | E29: =SUM(E20:E28) -> 147622 | F29: =D29-E29 -> 29378
A31: 🗂️ EXPENSE TYPE SUMMARY
A32: # | B32: Expense Type | D32: Total Amount (₹)
A33: 1 | B33: Aadi Festival | D33: =IFERROR(__xludf.DUMMYFUNCTION("IFERROR(INDEX(QUERY(IMPORTRANGE(""12PgU-zwv8gBrFfxvJpoPIPcxUHWup-vsxMH3HWUigZ8"",""💸 Expenses!F5:J200""),""SELECT SUM(Col1) WHERE Col5='Aadi Festival' LABEL SUM(Col1) ''""),1),0)"),70852.0) -> 70852
A34: 2 | B34: Temple Development | D34: =IFERROR(__xludf.DUMMYFUNCTION("IFERROR(INDEX(QUERY(IMPORTRANGE(""12PgU-zwv8gBrFfxvJpoPIPcxUHWup-vsxMH3HWUigZ8"",""💸 Expenses!F5:J200""),""SELECT SUM(Col1) WHERE Col5='Temple Development' LABEL SUM(Col1) ''""),1),0)"),76770.0) -> 76770
A35: 3 | B35: Temple Operations | D35: =IFERROR(__xludf.DUMMYFUNCTION("IFERROR(INDEX(QUERY(IMPORTRANGE(""12PgU-zwv8gBrFfxvJpoPIPcxUHWup-vsxMH3HWUigZ8"",""💸 Expenses!F5:J200""),""SELECT SUM(Col1) WHERE Col5='Temple Operations' LABEL SUM(Col1) ''""),1),0)"),0.0) -> 0
A36: 4 | B36: Others | D36: =IFERROR(__xludf.DUMMYFUNCTION("IFERROR(INDEX(QUERY(IMPORTRANGE(""12PgU-zwv8gBrFfxvJpoPIPcxUHWup-vsxMH3HWUigZ8"",""💸 Expenses!F5:J200""),""SELECT SUM(Col1) WHERE Col5='Others' LABEL SUM(Col1) ''""),1),0)"),0.0) -> 0
A37: TOTAL | D37: =SUM(D33:D36) -> 147622
A39: 💸 EXPENSE LOG
A40: # | B40: Date | C40: Vendor / Payee | D40: Description | E40: Category | F40: Amount (₹) | G40: Mode | H40: Paid By | I40: Remarks | J40: Type
A41: =IFERROR(__xludf.DUMMYFUNCTION("IFERROR(INDEX(IMPORTRANGE(""12PgU-zwv8gBrFfxvJpoPIPcxUHWup-vsxMH3HWUigZ8"",""💸 Expenses!A5:J200""),1,1),"""")"),"2026/EX/1") -> 2026/EX/1 | B41: =IFERROR(__xludf.DUMMYFUNCTION("IFERROR(IF(INDEX(IMPORTRANGE(""12PgU-zwv8gBrFfxvJpoPIPcxUHWup-vsxMH3HWUigZ8"",""💸 Expenses!A5:J200""),1,2)="""","""",TEXT(INDEX(IMPORTRANGE(""12PgU-zwv8gBrFfxvJpoPIPcxUHWup-vsxMH3HWUigZ8"",""💸 Expenses!A5:J200""),1,2),""DD-MM-YYYY"")),"""")"),"25-05-26") -> 25-05-26 | C41: =IFERROR(__xludf.DUMMYFUNCTION("IFERROR(INDEX(IMPORTRANGE(""12PgU-zwv8gBrFfxvJpoPIPcxUHWup-vsxMH3HWUigZ8"",""💸 Expenses!A5:J200""),1,3),"""")"),"Thimiri Press") -> Thimiri Press | D41: =IFERROR(__xludf.DUMMYFUNCTION("IFERROR(INDEX(IMPORTRANGE(""12PgU-zwv8gBrFfxvJpoPIPcxUHWup-vsxMH3HWUigZ8"",""💸 Expenses!A5:J200""),1,4),"""")"),"Card Printing") -> Card Printing | E41: =IFERROR(__xludf.DUMMYFUNCTION("IFERROR(INDEX(IMPORTRANGE(""12PgU-zwv8gBrFfxvJpoPIPcxUHWup-vsxMH3HWUigZ8"",""💸 Expenses!A5:J200""),1,5),"""")"),"Miscellaneous") -> Miscellaneous | F41: =IFERROR(__xludf.DUMMYFUNCTION("IFERROR(IFERROR(INDEX(IMPORTRANGE(""12PgU-zwv8gBrFfxvJpoPIPcxUHWup-vsxMH3HWUigZ8"",""💸 Expenses!A5:J200""),1,6)*1,0),0)"),500.0) -> 500 | G41: =IFERROR(__xludf.DUMMYFUNCTION("IFERROR(INDEX(IMPORTRANGE(""12PgU-zwv8gBrFfxvJpoPIPcxUHWup-vsxMH3HWUigZ8"",""💸 Expenses!A5:J200""),1,7),"""")"),"UPI") -> UPI | H41: =IFERROR(__xludf.DUMMYFUNCTION("IFERROR(INDEX(IMPORTRANGE(""12PgU-zwv8gBrFfxvJpoPIPcxUHWup-vsxMH3HWUigZ8"",""💸 Expenses!A5:J200""),1,8),"""")"),"Sunil Kumar") -> Sunil Kumar | I41: =IFERROR(__xludf.DUMMYFUNCTION("IFERROR(INDEX(IMPORTRANGE(""12PgU-zwv8gBrFfxvJpoPIPcxUHWup-vsxMH3HWUigZ8"",""💸 Expenses!A5:J200""),1,9),"""")"),"") | J41: =IFERROR(__xludf.DUMMYFUNCTION("IFERROR(INDEX(IMPORTRANGE(""12PgU-zwv8gBrFfxvJpoPIPcxUHWup-vsxMH3HWUigZ8"",""💸 Expenses!A5:J200""),1,10),"""")"),"Aadi Festival") -> Aadi Festival
A42: =IFERROR(__xludf.DUMMYFUNCTION("IFERROR(INDEX(IMPORTRANGE(""12PgU-zwv8gBrFfxvJpoPIPcxUHWup-vsxMH3HWUigZ8"",""💸 Expenses!A5:J200""),2,1),"""")"),"2026/EX/2") -> 2026/EX/2 | B42: =IFERROR(__xludf.DUMMYFUNCTION("IFERROR(IF(INDEX(IMPORTRANGE(""12PgU-zwv8gBrFfxvJpoPIPcxUHWup-vsxMH3HWUigZ8"",""💸 Expenses!A5:J200""),2,2)="""","""",TEXT(INDEX(IMPORTRANGE(""12PgU-zwv8gBrFfxvJpoPIPcxUHWup-vsxMH3HWUigZ8"",""💸 Expenses!A5:J200""),2,2),""DD-MM-YYYY"")),"""")"),"25-05-26") -> 25-05-26 | C42: =IFERROR(__xludf.DUMMYFUNCTION("IFERROR(INDEX(IMPORTRANGE(""12PgU-zwv8gBrFfxvJpoPIPcxUHWup-vsxMH3HWUigZ8"",""💸 Expenses!A5:J200""),2,3),"""")"),"Vadivelu / Saravana") -> Vadivelu / Saravana | D42: =IFERROR(__xludf.DUMMYFUNCTION("IFERROR(INDEX(IMPORTRANGE(""12PgU-zwv8gBrFfxvJpoPIPcxUHWup-vsxMH3HWUigZ8"",""💸 Expenses!A5:J200""),2,4),"""")"),"Iyer Booking") -> Iyer Booking | E42: =IFERROR(__xludf.DUMMYFUNCTION("IFERROR(INDEX(IMPORTRANGE(""12PgU-zwv8gBrFfxvJpoPIPcxUHWup-vsxMH3HWUigZ8"",""💸 Expenses!A5:J200""),2,5),"""")"),"Puja & Rituals") -> Puja & Rituals | F42: =IFERROR(__xludf.DUMMYFUNCTION("IFERROR(IFERROR(INDEX(IMPORTRANGE(""12PgU-zwv8gBrFfxvJpoPIPcxUHWup-vsxMH3HWUigZ8"",""💸 Expenses!A5:J200""),2,6)*1,0),0)"),5000.0) -> 5000 | G42: =IFERROR(__xludf.DUMMYFUNCTION("IFERROR(INDEX(IMPORTRANGE(""12PgU-zwv8gBrFfxvJpoPIPcxUHWup-vsxMH3HWUigZ8"",""💸 Expenses!A5:J200""),2,7),"""")"),"UPI") -> UPI | H42: =IFERROR(__xludf.DUMMYFUNCTION("IFERROR(INDEX(IMPORTRANGE(""12PgU-zwv8gBrFfxvJpoPIPcxUHWup-vsxMH3HWUigZ8"",""💸 Expenses!A5:J200""),2,8),"""")"),"Sunil Kumar") -> Sunil Kumar | I42: =IFERROR(__xludf.DUMMYFUNCTION("IFERROR(INDEX(IMPORTRANGE(""12PgU-zwv8gBrFfxvJpoPIPcxUHWup-vsxMH3HWUigZ8"",""💸 Expenses!A5:J200""),2,9),"""")"),"") | J42: =IFERROR(__xludf.DUMMYFUNCTION("IFERROR(INDEX(IMPORTRANGE(""12PgU-zwv8gBrFfxvJpoPIPcxUHWup-vsxMH3HWUigZ8"",""💸 Expenses!A5:J200""),2,10),"""")"),"Aadi Festival") -> Aadi Festival
A43: =IFERROR(__xludf.DUMMYFUNCTION("IFERROR(INDEX(IMPORTRANGE(""12PgU-zwv8gBrFfxvJpoPIPcxUHWup-vsxMH3HWUigZ8"",""💸 Expenses!A5:J200""),3,1),"""")"),"2026/EX/3") -> 2026/EX/3 | B43: =IFERROR(__xludf.DUMMYFUNCTION("IFERROR(IF(INDEX(IMPORTRANGE(""12PgU-zwv8gBrFfxvJpoPIPcxUHWup-vsxMH3HWUigZ8"",""💸 Expenses!A5:J200""),3,2)="""","""",TEXT(INDEX(IMPORTRANGE(""12PgU-zwv8gBrFfxvJpoPIPcxUHWup-vsxMH3HWUigZ8"",""💸 Expenses!A5:J200""),3,2),""DD-MM-YYYY"")),"""")"),"26-05-26") -> 26-05-26 | C43: =IFERROR(__xludf.DUMMYFUNCTION("IFERROR(INDEX(IMPORTRANGE(""12PgU-zwv8gBrFfxvJpoPIPcxUHWup-vsxMH3HWUigZ8"",""💸 Expenses!A5:J200""),3,3),"""")"),"Sathish B") -> Sathish B | D43: =IFERROR(__xludf.DUMMYFUNCTION("IFERROR(INDEX(IMPORTRANGE(""12PgU-zwv8gBrFfxvJpoPIPcxUHWup-vsxMH3HWUigZ8"",""💸 Expenses!A5:J200""),3,4),"""")"),"Vessels & Utensils") -> Vessels & Utensils | E43: =IFERROR(__xludf.DUMMYFUNCTION("IFERROR(INDEX(IMPORTRANGE(""12PgU-zwv8gBrFfxvJpoPIPcxUHWup-vsxMH3HWUigZ8"",""💸 Expenses!A5:J200""),3,5),"""")"),"Infrastructure & Logistics") -> Infrastructure & Logistics | F43: =IFERROR(__xludf.DUMMYFUNCTION("IFERROR(IFERROR(INDEX(IMPORTRANGE(""12PgU-zwv8gBrFfxvJpoPIPcxUHWup-vsxMH3HWUigZ8"",""💸 Expenses!A5:J200""),3,6)*1,0),0)"),2001.0) -> 2001 | G43: =IFERROR(__xludf.DUMMYFUNCTION("IFERROR(INDEX(IMPORTRANGE(""12PgU-zwv8gBrFfxvJpoPIPcxUHWup-vsxMH3HWUigZ8"",""💸 Expenses!A5:J200""),3,7),"""")"),"UPI") -> UPI | H43: =IFERROR(__xludf.DUMMYFUNCTION("IFERROR(INDEX(IMPORTRANGE(""12PgU-zwv8gBrFfxvJpoPIPcxUHWup-vsxMH3HWUigZ8"",""💸 Expenses!A5:J200""),3,8),"""")"),"Sunil Kumar") -> Sunil Kumar | I43: =IFERROR(__xludf.DUMMYFUNCTION("IFERROR(INDEX(IMPORTRANGE(""12PgU-zwv8gBrFfxvJpoPIPcxUHWup-vsxMH3HWUigZ8"",""💸 Expenses!A5:J200""),3,9),"""")"),"") | J43: =IFERROR(__xludf.DUMMYFUNCTION("IFERROR(INDEX(IMPORTRANGE(""12PgU-zwv8gBrFfxvJpoPIPcxUHWup-vsxMH3HWUigZ8"",""💸 Expenses!A5:J200""),3,10),"""")"),"Aadi Festival") -> Aadi Festival
A44: =IFERROR(__xludf.DUMMYFUNCTION("IFERROR(INDEX(IMPORTRANGE(""12PgU-zwv8gBrFfxvJpoPIPcxUHWup-vsxMH3HWUigZ8"",""💸 Expenses!A5:J200""),4,1),"""")"),"2026/EX/4") -> 2026/EX/4 | B44: =IFERROR(__xludf.DUMMYFUNCTION("IFERROR(IF(INDEX(IMPORTRANGE(""12PgU-zwv8gBrFfxvJpoPIPcxUHWup-vsxMH3HWUigZ8"",""💸 Expenses!A5:J200""),4,2)="""","""",TEXT(INDEX(IMPORTRANGE(""12PgU-zwv8gBrFfxvJpoPIPcxUHWup-vsxMH3HWUigZ8"",""💸 Expenses!A5:J200""),4,2),""DD-MM-YYYY"")),"""")"),"26-05-26") -> 26-05-26 | C44: =IFERROR(__xludf.DUMMYFUNCTION("IFERROR(INDEX(IMPORTRANGE(""12PgU-zwv8gBrFfxvJpoPIPcxUHWup-vsxMH3HWUigZ8"",""💸 Expenses!A5:J200""),4,3),"""")"),"Karthik") -> Karthik | D44: =IFERROR(__xludf.DUMMYFUNCTION("IFERROR(INDEX(IMPORTRANGE(""12PgU-zwv8gBrFfxvJpoPIPcxUHWup-vsxMH3HWUigZ8"",""💸 Expenses!A5:J200""),4,4),"""")"),"Electrical Lighting & Generator Mic & Sound system") -> Electrical Lighting & Generator Mic & Sound system | E44: =IFERROR(__xludf.DUMMYFUNCTION("IFERROR(INDEX(IMPORTRANGE(""12PgU-zwv8gBrFfxvJpoPIPcxUHWup-vsxMH3HWUigZ8"",""💸 Expenses!A5:J200""),4,5),"""")"),"Infrastructure & Logistics") -> Infrastructure & Logistics | F44: =IFERROR(__xludf.DUMMYFUNCTION("IFERROR(IFERROR(INDEX(IMPORTRANGE(""12PgU-zwv8gBrFfxvJpoPIPcxUHWup-vsxMH3HWUigZ8"",""💸 Expenses!A5:J200""),4,6)*1,0),0)"),2001.0) -> 2001 | G44: =IFERROR(__xludf.DUMMYFUNCTION("IFERROR(INDEX(IMPORTRANGE(""12PgU-zwv8gBrFfxvJpoPIPcxUHWup-vsxMH3HWUigZ8"",""💸 Expenses!A5:J200""),4,7),"""")"),"UPI") -> UPI | H44: =IFERROR(__xludf.DUMMYFUNCTION("IFERROR(INDEX(IMPORTRANGE(""12PgU-zwv8gBrFfxvJpoPIPcxUHWup-vsxMH3HWUigZ8"",""💸 Expenses!A5:J200""),4,8),"""")"),"Sunil Kumar") -> Sunil Kumar | I44: =IFERROR(__xludf.DUMMYFUNCTION("IFERROR(INDEX(IMPORTRANGE(""12PgU-zwv8gBrFfxvJpoPIPcxUHWup-vsxMH3HWUigZ8"",""💸 Expenses!A5:J200""),4,9),"""")"),"") | J44: =IFERROR(__xludf.DUMMYFUNCTION("IFERROR(INDEX(IMPORTRANGE(""12PgU-zwv8gBrFfxvJpoPIPcxUHWup-vsxMH3HWUigZ8"",""💸 Expenses!A5:J200""),4,10),"""")"),"Aadi Festival") -> Aadi Festival
A45: =IFERROR(__xludf.DUMMYFUNCTION("IFERROR(INDEX(IMPORTRANGE(""12PgU-zwv8gBrFfxvJpoPIPcxUHWup-vsxMH3HWUigZ8"",""💸 Expenses!A5:J200""),5,1),"""")"),"2026/EX/5") -> 2026/EX/5 | B45: =IFERROR(__xludf.DUMMYFUNCTION("IFERROR(IF(INDEX(IMPORTRANGE(""12PgU-zwv8gBrFfxvJpoPIPcxUHWup-vsxMH3HWUigZ8"",""💸 Expenses!A5:J200""),5,2)="""","""",TEXT(INDEX(IMPORTRANGE(""12PgU-zwv8gBrFfxvJpoPIPcxUHWup-vsxMH3HWUigZ8"",""💸 Expenses!A5:J200""),5,2),""DD-MM-YYYY"")),"""")"),"26-05-26") -> 26-05-26 | C45: =IFERROR(__xludf.DUMMYFUNCTION("IFERROR(INDEX(IMPORTRANGE(""12PgU-zwv8gBrFfxvJpoPIPcxUHWup-vsxMH3HWUigZ8"",""💸 Expenses!A5:J200""),5,3),"""")"),"Elagovan") -> Elagovan | D45: =IFERROR(__xludf.DUMMYFUNCTION("IFERROR(INDEX(IMPORTRANGE(""12PgU-zwv8gBrFfxvJpoPIPcxUHWup-vsxMH3HWUigZ8"",""💸 Expenses!A5:J200""),5,4),"""")"),"Flowers & Flower decoration for Chariot") -> Flowers & Flower decoration for Chariot | E45: =IFERROR(__xludf.DUMMYFUNCTION("IFERROR(INDEX(IMPORTRANGE(""12PgU-zwv8gBrFfxvJpoPIPcxUHWup-vsxMH3HWUigZ8"",""💸 Expenses!A5:J200""),5,5),"""")"),"Decorations & Flowers") -> Decorations & Flowers | F45: =IFERROR(__xludf.DUMMYFUNCTION("IFERROR(IFERROR(INDEX(IMPORTRANGE(""12PgU-zwv8gBrFfxvJpoPIPcxUHWup-vsxMH3HWUigZ8"",""💸 Expenses!A5:J200""),5,6)*1,0),0)"),5001.0) -> 5001 | G45: =IFERROR(__xludf.DUMMYFUNCTION("IFERROR(INDEX(IMPORTRANGE(""12PgU-zwv8gBrFfxvJpoPIPcxUHWup-vsxMH3HWUigZ8"",""💸 Expenses!A5:J200""),5,7),"""")"),"UPI") -> UPI | H45: =IFERROR(__xludf.DUMMYFUNCTION("IFERROR(INDEX(IMPORTRANGE(""12PgU-zwv8gBrFfxvJpoPIPcxUHWup-vsxMH3HWUigZ8"",""💸 Expenses!A5:J200""),5,8),"""")"),"Sunil Kumar") -> Sunil Kumar | I45: =IFERROR(__xludf.DUMMYFUNCTION("IFERROR(INDEX(IMPORTRANGE(""12PgU-zwv8gBrFfxvJpoPIPcxUHWup-vsxMH3HWUigZ8"",""💸 Expenses!A5:J200""),5,9),"""")"),"") | J45: =IFERROR(__xludf.DUMMYFUNCTION("IFERROR(INDEX(IMPORTRANGE(""12PgU-zwv8gBrFfxvJpoPIPcxUHWup-vsxMH3HWUigZ8"",""💸 Expenses!A5:J200""),5,10),"""")"),"Aadi Festival") -> Aadi Festival
...

Sheet 2027
A1: 🕉 SRI PONNIAMMAN TEMPLE — ANNUAL ACCOUNTS 2027 🕉
A2: Financial Year: 2027 | Live data via Google Sheets IMPORTRANGE
A4: 🎪 FESTIVALS / EVENTS IN THIS YEAR
A5: # | B5: Festival / Event | D5: Date | E5: Notes / Description
A6: 1
A8: 📊 ANNUAL SUMMARY
A9: Annual Budget (₹) | D9: =SUM(D20:D28) -> 0
A10: Total Donations Pledged (₹) | D10: =IFERROR(__xludf.DUMMYFUNCTION("IFERROR(INDEX(QUERY(IMPORTRANGE(""1wF8uimz-gnzzmqfjHb8Ua7fudqcoq5SrFyToq2B2IO0"",""💰 Donations!A4:D200""),""SELECT SUM(Col3) WHERE Col1 LIKE '2027/D/%' LABEL SUM(Col3) ''""),1),0)"),0.0) -> 0
A11: Donations Received (₹) | D11: =IFERROR(__xludf.DUMMYFUNCTION("IFERROR(INDEX(QUERY(IMPORTRANGE(""1wF8uimz-gnzzmqfjHb8Ua7fudqcoq5SrFyToq2B2IO0"",""💰 Donations!A4:D200""),""SELECT SUM(Col4) WHERE Col1 LIKE '2027/D/%' LABEL SUM(Col4) ''""),1),0)"),0.0) -> 0
A12: Donations Pending (₹) | D12: =D10-D11 -> 0
A13: In-Kind Donations (₹) | D13: =IFERROR(__xludf.DUMMYFUNCTION("IFERROR(INDEX(QUERY(IMPORTRANGE(""1wF8uimz-gnzzmqfjHb8Ua7fudqcoq5SrFyToq2B2IO0"",""🌿 In-Kind!A4:E200""),""SELECT SUM(Col5) WHERE Col1 LIKE '2027/IK/%' LABEL SUM(Col5) ''""),1),0)"),0.0) -> 0
A14: Total Expenses (₹) | D14: =IFERROR(__xludf.DUMMYFUNCTION("IFERROR(INDEX(QUERY(IMPORTRANGE(""1wF8uimz-gnzzmqfjHb8Ua7fudqcoq5SrFyToq2B2IO0"",""💸 Expenses!A5:F200""),""SELECT SUM(Col6) WHERE Col1 LIKE '2027/EX/%' LABEL SUM(Col6) ''""),1),0)"),0.0) -> 0
A15: Net Surplus / (Deficit) (₹) | D15: =D9-D14 -> 0
A16: Total Donors | D16: =IFERROR(__xludf.DUMMYFUNCTION("IFERROR(INDEX(QUERY(IMPORTRANGE(""1wF8uimz-gnzzmqfjHb8Ua7fudqcoq5SrFyToq2B2IO0"",""💰 Donations!A4:D200""),""SELECT COUNT(Col1) WHERE Col1 LIKE '2027/D/%' LABEL COUNT(Col1) ''""),1),0)"),1.0) -> 1
A18: 💰 EXPENSE CATEGORY BREAKDOWN (Budget vs Actual)
A19: # | B19: Category | C19: Group | D19: Budget (₹) | E19: Actual (₹) | F19: Balance (₹)
A20: 1 | B20: Puja & Rituals | C20: Aadi Festival | D20: =IFERROR(__xludf.DUMMYFUNCTION("IFERROR(INDEX(QUERY(IMPORTRANGE(""1wF8uimz-gnzzmqfjHb8Ua7fudqcoq5SrFyToq2B2IO0"",""💰 Budget!C5:E200""),""SELECT SUM(Col3) WHERE Col1='Puja & Rituals' LABEL SUM(Col3) ''""),1),0)"),0.0) -> 0 | E20: =IFERROR(__xludf.DUMMYFUNCTION("IFERROR(INDEX(QUERY(IMPORTRANGE(""1wF8uimz-gnzzmqfjHb8Ua7fudqcoq5SrFyToq2B2IO0"",""💸 Expenses!E5:F200""),""SELECT SUM(Col2) WHERE Col1='Puja & Rituals' LABEL SUM(Col2) ''""),1),0)"),0.0) -> 0 | F20: =D20-E20 -> 0
A21: 2 | B21: Decorations & Flowers | C21: Aadi Festival | D21: =IFERROR(__xludf.DUMMYFUNCTION("IFERROR(INDEX(QUERY(IMPORTRANGE(""1wF8uimz-gnzzmqfjHb8Ua7fudqcoq5SrFyToq2B2IO0"",""💰 Budget!C5:E200""),""SELECT SUM(Col3) WHERE Col1='Decorations & Flowers' LABEL SUM(Col3) ''""),1),0)"),0.0) -> 0 | E21: =IFERROR(__xludf.DUMMYFUNCTION("IFERROR(INDEX(QUERY(IMPORTRANGE(""1wF8uimz-gnzzmqfjHb8Ua7fudqcoq5SrFyToq2B2IO0"",""💸 Expenses!E5:F200""),""SELECT SUM(Col2) WHERE Col1='Decorations & Flowers' LABEL SUM(Col2) ''""),1),0)"),0.0) -> 0 | F21: =D21-E21 -> 0
A22: 3 | B22: Food & Catering | C22: Aadi Festival | D22: =IFERROR(__xludf.DUMMYFUNCTION("IFERROR(INDEX(QUERY(IMPORTRANGE(""1wF8uimz-gnzzmqfjHb8Ua7fudqcoq5SrFyToq2B2IO0"",""💰 Budget!C5:E200""),""SELECT SUM(Col3) WHERE Col1='Food & Catering' LABEL SUM(Col3) ''""),1),0)"),0.0) -> 0 | E22: =IFERROR(__xludf.DUMMYFUNCTION("IFERROR(INDEX(QUERY(IMPORTRANGE(""1wF8uimz-gnzzmqfjHb8Ua7fudqcoq5SrFyToq2B2IO0"",""💸 Expenses!E5:F200""),""SELECT SUM(Col2) WHERE Col1='Food & Catering' LABEL SUM(Col2) ''""),1),0)"),0.0) -> 0 | F22: =D22-E22 -> 0
A23: 4 | B23: Infrastructure & Logistics | C23: Aadi Festival | D23: =IFERROR(__xludf.DUMMYFUNCTION("IFERROR(INDEX(QUERY(IMPORTRANGE(""1wF8uimz-gnzzmqfjHb8Ua7fudqcoq5SrFyToq2B2IO0"",""💰 Budget!C5:E200""),""SELECT SUM(Col3) WHERE Col1='Infrastructure & Logistics' LABEL SUM(Col3) ''""),1),0)"),0.0) -> 0 | E23: =IFERROR(__xludf.DUMMYFUNCTION("IFERROR(INDEX(QUERY(IMPORTRANGE(""1wF8uimz-gnzzmqfjHb8Ua7fudqcoq5SrFyToq2B2IO0"",""💸 Expenses!E5:F200""),""SELECT SUM(Col2) WHERE Col1='Infrastructure & Logistics' LABEL SUM(Col2) ''""),1),0)"),0.0) -> 0 | F23: =D23-E23 -> 0
A24: 5 | B24: Miscellaneous | C24: Aadi Festival | D24: =IFERROR(__xludf.DUMMYFUNCTION("IFERROR(INDEX(QUERY(IMPORTRANGE(""1wF8uimz-gnzzmqfjHb8Ua7fudqcoq5SrFyToq2B2IO0"",""💰 Budget!C5:E200""),""SELECT SUM(Col3) WHERE Col1='Miscellaneous' LABEL SUM(Col3) ''""),1),0)"),0.0) -> 0 | E24: =IFERROR(__xludf.DUMMYFUNCTION("IFERROR(INDEX(QUERY(IMPORTRANGE(""1wF8uimz-gnzzmqfjHb8Ua7fudqcoq5SrFyToq2B2IO0"",""💸 Expenses!E5:F200""),""SELECT SUM(Col2) WHERE Col1='Miscellaneous' LABEL SUM(Col2) ''""),1),0)"),0.0) -> 0 | F24: =D24-E24 -> 0
A25: 6 | B25: Materials | C25: Temple Development | D25: =IFERROR(__xludf.DUMMYFUNCTION("IFERROR(INDEX(QUERY(IMPORTRANGE(""1wF8uimz-gnzzmqfjHb8Ua7fudqcoq5SrFyToq2B2IO0"",""💰 Budget!C5:E200""),""SELECT SUM(Col3) WHERE Col1='Materials' LABEL SUM(Col3) ''""),1),0)"),0.0) -> 0 | E25: =IFERROR(__xludf.DUMMYFUNCTION("IFERROR(INDEX(QUERY(IMPORTRANGE(""1wF8uimz-gnzzmqfjHb8Ua7fudqcoq5SrFyToq2B2IO0"",""💸 Expenses!E5:F200""),""SELECT SUM(Col2) WHERE Col1='Materials' LABEL SUM(Col2) ''""),1),0)"),0.0) -> 0 | F25: =D25-E25 -> 0
A26: 7 | B26: Labour | C26: Temple Development | D26: =IFERROR(__xludf.DUMMYFUNCTION("IFERROR(INDEX(QUERY(IMPORTRANGE(""1wF8uimz-gnzzmqfjHb8Ua7fudqcoq5SrFyToq2B2IO0"",""💰 Budget!C5:E200""),""SELECT SUM(Col3) WHERE Col1='Labour' LABEL SUM(Col3) ''""),1),0)"),0.0) -> 0 | E26: =IFERROR(__xludf.DUMMYFUNCTION("IFERROR(INDEX(QUERY(IMPORTRANGE(""1wF8uimz-gnzzmqfjHb8Ua7fudqcoq5SrFyToq2B2IO0"",""💸 Expenses!E5:F200""),""SELECT SUM(Col2) WHERE Col1='Labour' LABEL SUM(Col2) ''""),1),0)"),0.0) -> 0 | F26: =D26-E26 -> 0
A27: 8 | B27: Transport | C27: Temple Development | D27: =IFERROR(__xludf.DUMMYFUNCTION("IFERROR(INDEX(QUERY(IMPORTRANGE(""1wF8uimz-gnzzmqfjHb8Ua7fudqcoq5SrFyToq2B2IO0"",""💰 Budget!C5:E200""),""SELECT SUM(Col3) WHERE Col1='Transport' LABEL SUM(Col3) ''""),1),0)"),0.0) -> 0 | E27: =IFERROR(__xludf.DUMMYFUNCTION("IFERROR(INDEX(QUERY(IMPORTRANGE(""1wF8uimz-gnzzmqfjHb8Ua7fudqcoq5SrFyToq2B2IO0"",""💸 Expenses!E5:F200""),""SELECT SUM(Col2) WHERE Col1='Transport' LABEL SUM(Col2) ''""),1),0)"),0.0) -> 0 | F27: =D27-E27 -> 0
A28: 9 | B28: Food | C28: Temple Development | D28: =IFERROR(__xludf.DUMMYFUNCTION("IFERROR(INDEX(QUERY(IMPORTRANGE(""1wF8uimz-gnzzmqfjHb8Ua7fudqcoq5SrFyToq2B2IO0"",""💰 Budget!C5:E200""),""SELECT SUM(Col3) WHERE Col1='Food' LABEL SUM(Col3) ''""),1),0)"),0.0) -> 0 | E28: =IFERROR(__xludf.DUMMYFUNCTION("IFERROR(INDEX(QUERY(IMPORTRANGE(""1wF8uimz-gnzzmqfjHb8Ua7fudqcoq5SrFyToq2B2IO0"",""💸 Expenses!E5:F200""),""SELECT SUM(Col2) WHERE Col1='Food' LABEL SUM(Col2) ''""),1),0)"),0.0) -> 0 | F28: =D28-E28 -> 0
A29: TOTAL ALL CATEGORIES | D29: =SUM(D20:D28) -> 0 | E29: =SUM(E20:E28) -> 0 | F29: =D29-E29 -> 0
A31: 🗂️ EXPENSE TYPE SUMMARY
A32: # | B32: Expense Type | D32: Total Amount (₹)
A33: 1 | B33: Aadi Festival | D33: =IFERROR(__xludf.DUMMYFUNCTION("IFERROR(INDEX(QUERY(IMPORTRANGE(""1wF8uimz-gnzzmqfjHb8Ua7fudqcoq5SrFyToq2B2IO0"",""💸 Expenses!F5:J200""),""SELECT SUM(Col1) WHERE Col5='Aadi Festival' LABEL SUM(Col1) ''""),1),0)"),0.0) -> 0
A34: 2 | B34: Temple Development | D34: =IFERROR(__xludf.DUMMYFUNCTION("IFERROR(INDEX(QUERY(IMPORTRANGE(""1wF8uimz-gnzzmqfjHb8Ua7fudqcoq5SrFyToq2B2IO0"",""💸 Expenses!F5:J200""),""SELECT SUM(Col1) WHERE Col5='Temple Development' LABEL SUM(Col1) ''""),1),0)"),0.0) -> 0
A35: 3 | B35: Temple Operations | D35: =IFERROR(__xludf.DUMMYFUNCTION("IFERROR(INDEX(QUERY(IMPORTRANGE(""1wF8uimz-gnzzmqfjHb8Ua7fudqcoq5SrFyToq2B2IO0"",""💸 Expenses!F5:J200""),""SELECT SUM(Col1) WHERE Col5='Temple Operations' LABEL SUM(Col1) ''""),1),0)"),0.0) -> 0
A36: 4 | B36: Others | D36: =IFERROR(__xludf.DUMMYFUNCTION("IFERROR(INDEX(QUERY(IMPORTRANGE(""1wF8uimz-gnzzmqfjHb8Ua7fudqcoq5SrFyToq2B2IO0"",""💸 Expenses!F5:J200""),""SELECT SUM(Col1) WHERE Col5='Others' LABEL SUM(Col1) ''""),1),0)"),0.0) -> 0
A37: TOTAL | D37: =SUM(D33:D36) -> 0
A39: 💸 EXPENSE LOG
A40: # | B40: Date | C40: Vendor / Payee | D40: Description | E40: Category | F40: Amount (₹) | G40: Mode | H40: Paid By | I40: Remarks | J40: Type
A41: =IFERROR(__xludf.DUMMYFUNCTION("IFERROR(INDEX(IMPORTRANGE(""1wF8uimz-gnzzmqfjHb8Ua7fudqcoq5SrFyToq2B2IO0"",""💸 Expenses!A5:J200""),1,1),"""")"),"2027/EX/1") -> 2027/EX/1 | B41: =IFERROR(__xludf.DUMMYFUNCTION("IFERROR(IF(INDEX(IMPORTRANGE(""1wF8uimz-gnzzmqfjHb8Ua7fudqcoq5SrFyToq2B2IO0"",""💸 Expenses!A5:J200""),1,2)="""","""",TEXT(INDEX(IMPORTRANGE(""1wF8uimz-gnzzmqfjHb8Ua7fudqcoq5SrFyToq2B2IO0"",""💸 Expenses!A5:J200""),1,2),""DD-MM-YYYY"")),"""")"),"25-05-26") -> 25-05-26 | C41: =IFERROR(__xludf.DUMMYFUNCTION("IFERROR(INDEX(IMPORTRANGE(""1wF8uimz-gnzzmqfjHb8Ua7fudqcoq5SrFyToq2B2IO0"",""💸 Expenses!A5:J200""),1,3),"""")"),"Thimiri Press") -> Thimiri Press | D41: =IFERROR(__xludf.DUMMYFUNCTION("IFERROR(INDEX(IMPORTRANGE(""1wF8uimz-gnzzmqfjHb8Ua7fudqcoq5SrFyToq2B2IO0"",""💸 Expenses!A5:J200""),1,4),"""")"),"Card Printing") -> Card Printing | E41: =IFERROR(__xludf.DUMMYFUNCTION("IFERROR(INDEX(IMPORTRANGE(""1wF8uimz-gnzzmqfjHb8Ua7fudqcoq5SrFyToq2B2IO0"",""💸 Expenses!A5:J200""),1,5),"""")"),"Miscellaneous") -> Miscellaneous | F41: =IFERROR(__xludf.DUMMYFUNCTION("IFERROR(IFERROR(INDEX(IMPORTRANGE(""1wF8uimz-gnzzmqfjHb8Ua7fudqcoq5SrFyToq2B2IO0"",""💸 Expenses!A5:J200""),1,6)*1,0),0)"),0.0) -> 0 | G41: =IFERROR(__xludf.DUMMYFUNCTION("IFERROR(INDEX(IMPORTRANGE(""1wF8uimz-gnzzmqfjHb8Ua7fudqcoq5SrFyToq2B2IO0"",""💸 Expenses!A5:J200""),1,7),"""")"),"UPI") -> UPI | H41: =IFERROR(__xludf.DUMMYFUNCTION("IFERROR(INDEX(IMPORTRANGE(""1wF8uimz-gnzzmqfjHb8Ua7fudqcoq5SrFyToq2B2IO0"",""💸 Expenses!A5:J200""),1,8),"""")"),"Sunil Kumar") -> Sunil Kumar | I41: =IFERROR(__xludf.DUMMYFUNCTION("IFERROR(INDEX(IMPORTRANGE(""1wF8uimz-gnzzmqfjHb8Ua7fudqcoq5SrFyToq2B2IO0"",""💸 Expenses!A5:J200""),1,9),"""")"),"") | J41: =IFERROR(__xludf.DUMMYFUNCTION("IFERROR(INDEX(IMPORTRANGE(""1wF8uimz-gnzzmqfjHb8Ua7fudqcoq5SrFyToq2B2IO0"",""💸 Expenses!A5:J200""),1,10),"""")"),"Aadi Festival") -> Aadi Festival
A42: =IFERROR(__xludf.DUMMYFUNCTION("IFERROR(INDEX(IMPORTRANGE(""1wF8uimz-gnzzmqfjHb8Ua7fudqcoq5SrFyToq2B2IO0"",""💸 Expenses!A5:J200""),2,1),"""")"),"") | B42: =IFERROR(__xludf.DUMMYFUNCTION("IFERROR(IF(INDEX(IMPORTRANGE(""1wF8uimz-gnzzmqfjHb8Ua7fudqcoq5SrFyToq2B2IO0"",""💸 Expenses!A5:J200""),2,2)="""","""",TEXT(INDEX(IMPORTRANGE(""1wF8uimz-gnzzmqfjHb8Ua7fudqcoq5SrFyToq2B2IO0"",""💸 Expenses!A5:J200""),2,2),""DD-MM-YYYY"")),"""")"),"") | C42: =IFERROR(__xludf.DUMMYFUNCTION("IFERROR(INDEX(IMPORTRANGE(""1wF8uimz-gnzzmqfjHb8Ua7fudqcoq5SrFyToq2B2IO0"",""💸 Expenses!A5:J200""),2,3),"""")"),"") | D42: =IFERROR(__xludf.DUMMYFUNCTION("IFERROR(INDEX(IMPORTRANGE(""1wF8uimz-gnzzmqfjHb8Ua7fudqcoq5SrFyToq2B2IO0"",""💸 Expenses!A5:J200""),2,4),"""")"),"") | E42: =IFERROR(__xludf.DUMMYFUNCTION("IFERROR(INDEX(IMPORTRANGE(""1wF8uimz-gnzzmqfjHb8Ua7fudqcoq5SrFyToq2B2IO0"",""💸 Expenses!A5:J200""),2,5),"""")"),"") | F42: =IFERROR(__xludf.DUMMYFUNCTION("IFERROR(IFERROR(INDEX(IMPORTRANGE(""1wF8uimz-gnzzmqfjHb8Ua7fudqcoq5SrFyToq2B2IO0"",""💸 Expenses!A5:J200""),2,6)*1,0),0)"),0.0) -> 0 | G42: =IFERROR(__xludf.DUMMYFUNCTION("IFERROR(INDEX(IMPORTRANGE(""1wF8uimz-gnzzmqfjHb8Ua7fudqcoq5SrFyToq2B2IO0"",""💸 Expenses!A5:J200""),2,7),"""")"),"") | H42: =IFERROR(__xludf.DUMMYFUNCTION("IFERROR(INDEX(IMPORTRANGE(""1wF8uimz-gnzzmqfjHb8Ua7fudqcoq5SrFyToq2B2IO0"",""💸 Expenses!A5:J200""),2,8),"""")"),"") | I42: =IFERROR(__xludf.DUMMYFUNCTION("IFERROR(INDEX(IMPORTRANGE(""1wF8uimz-gnzzmqfjHb8Ua7fudqcoq5SrFyToq2B2IO0"",""💸 Expenses!A5:J200""),2,9),"""")"),"") | J42: =IFERROR(__xludf.DUMMYFUNCTION("IFERROR(INDEX(IMPORTRANGE(""1wF8uimz-gnzzmqfjHb8Ua7fudqcoq5SrFyToq2B2IO0"",""💸 Expenses!A5:J200""),2,10),"""")"),"")
A43: =IFERROR(__xludf.DUMMYFUNCTION("IFERROR(INDEX(IMPORTRANGE(""1wF8uimz-gnzzmqfjHb8Ua7fudqcoq5SrFyToq2B2IO0"",""💸 Expenses!A5:J200""),3,1),"""")"),"") | B43: =IFERROR(__xludf.DUMMYFUNCTION("IFERROR(IF(INDEX(IMPORTRANGE(""1wF8uimz-gnzzmqfjHb8Ua7fudqcoq5SrFyToq2B2IO0"",""💸 Expenses!A5:J200""),3,2)="""","""",TEXT(INDEX(IMPORTRANGE(""1wF8uimz-gnzzmqfjHb8Ua7fudqcoq5SrFyToq2B2IO0"",""💸 Expenses!A5:J200""),3,2),""DD-MM-YYYY"")),"""")"),"") | C43: =IFERROR(__xludf.DUMMYFUNCTION("IFERROR(INDEX(IMPORTRANGE(""1wF8uimz-gnzzmqfjHb8Ua7fudqcoq5SrFyToq2B2IO0"",""💸 Expenses!A5:J200""),3,3),"""")"),"") | D43: =IFERROR(__xludf.DUMMYFUNCTION("IFERROR(INDEX(IMPORTRANGE(""1wF8uimz-gnzzmqfjHb8Ua7fudqcoq5SrFyToq2B2IO0"",""💸 Expenses!A5:J200""),3,4),"""")"),"") | E43: =IFERROR(__xludf.DUMMYFUNCTION("IFERROR(INDEX(IMPORTRANGE(""1wF8uimz-gnzzmqfjHb8Ua7fudqcoq5SrFyToq2B2IO0"",""💸 Expenses!A5:J200""),3,5),"""")"),"") | F43: =IFERROR(__xludf.DUMMYFUNCTION("IFERROR(IFERROR(INDEX(IMPORTRANGE(""1wF8uimz-gnzzmqfjHb8Ua7fudqcoq5SrFyToq2B2IO0"",""💸 Expenses!A5:J200""),3,6)*1,0),0)"),0.0) -> 0 | G43: =IFERROR(__xludf.DUMMYFUNCTION("IFERROR(INDEX(IMPORTRANGE(""1wF8uimz-gnzzmqfjHb8Ua7fudqcoq5SrFyToq2B2IO0"",""💸 Expenses!A5:J200""),3,7),"""")"),"") | H43: =IFERROR(__xludf.DUMMYFUNCTION("IFERROR(INDEX(IMPORTRANGE(""1wF8uimz-gnzzmqfjHb8Ua7fudqcoq5SrFyToq2B2IO0"",""💸 Expenses!A5:J200""),3,8),"""")"),"") | I43: =IFERROR(__xludf.DUMMYFUNCTION("IFERROR(INDEX(IMPORTRANGE(""1wF8uimz-gnzzmqfjHb8Ua7fudqcoq5SrFyToq2B2IO0"",""💸 Expenses!A5:J200""),3,9),"""")"),"") | J43: =IFERROR(__xludf.DUMMYFUNCTION("IFERROR(INDEX(IMPORTRANGE(""1wF8uimz-gnzzmqfjHb8Ua7fudqcoq5SrFyToq2B2IO0"",""💸 Expenses!A5:J200""),3,10),"""")"),"")
A44: =IFERROR(__xludf.DUMMYFUNCTION("IFERROR(INDEX(IMPORTRANGE(""1wF8uimz-gnzzmqfjHb8Ua7fudqcoq5SrFyToq2B2IO0"",""💸 Expenses!A5:J200""),4,1),"""")"),"") | B44: =IFERROR(__xludf.DUMMYFUNCTION("IFERROR(IF(INDEX(IMPORTRANGE(""1wF8uimz-gnzzmqfjHb8Ua7fudqcoq5SrFyToq2B2IO0"",""💸 Expenses!A5:J200""),4,2)="""","""",TEXT(INDEX(IMPORTRANGE(""1wF8uimz-gnzzmqfjHb8Ua7fudqcoq5SrFyToq2B2IO0"",""💸 Expenses!A5:J200""),4,2),""DD-MM-YYYY"")),"""")"),"") | C44: =IFERROR(__xludf.DUMMYFUNCTION("IFERROR(INDEX(IMPORTRANGE(""1wF8uimz-gnzzmqfjHb8Ua7fudqcoq5SrFyToq2B2IO0"",""💸 Expenses!A5:J200""),4,3),"""")"),"") | D44: =IFERROR(__xludf.DUMMYFUNCTION("IFERROR(INDEX(IMPORTRANGE(""1wF8uimz-gnzzmqfjHb8Ua7fudqcoq5SrFyToq2B2IO0"",""💸 Expenses!A5:J200""),4,4),"""")"),"") | E44: =IFERROR(__xludf.DUMMYFUNCTION("IFERROR(INDEX(IMPORTRANGE(""1wF8uimz-gnzzmqfjHb8Ua7fudqcoq5SrFyToq2B2IO0"",""💸 Expenses!A5:J200""),4,5),"""")"),"") | F44: =IFERROR(__xludf.DUMMYFUNCTION("IFERROR(IFERROR(INDEX(IMPORTRANGE(""1wF8uimz-gnzzmqfjHb8Ua7fudqcoq5SrFyToq2B2IO0"",""💸 Expenses!A5:J200""),4,6)*1,0),0)"),0.0) -> 0 | G44: =IFERROR(__xludf.DUMMYFUNCTION("IFERROR(INDEX(IMPORTRANGE(""1wF8uimz-gnzzmqfjHb8Ua7fudqcoq5SrFyToq2B2IO0"",""💸 Expenses!A5:J200""),4,7),"""")"),"") | H44: =IFERROR(__xludf.DUMMYFUNCTION("IFERROR(INDEX(IMPORTRANGE(""1wF8uimz-gnzzmqfjHb8Ua7fudqcoq5SrFyToq2B2IO0"",""💸 Expenses!A5:J200""),4,8),"""")"),"") | I44: =IFERROR(__xludf.DUMMYFUNCTION("IFERROR(INDEX(IMPORTRANGE(""1wF8uimz-gnzzmqfjHb8Ua7fudqcoq5SrFyToq2B2IO0"",""💸 Expenses!A5:J200""),4,9),"""")"),"") | J44: =IFERROR(__xludf.DUMMYFUNCTION("IFERROR(INDEX(IMPORTRANGE(""1wF8uimz-gnzzmqfjHb8Ua7fudqcoq5SrFyToq2B2IO0"",""💸 Expenses!A5:J200""),4,10),"""")"),"")
A45: =IFERROR(__xludf.DUMMYFUNCTION("IFERROR(INDEX(IMPORTRANGE(""1wF8uimz-gnzzmqfjHb8Ua7fudqcoq5SrFyToq2B2IO0"",""💸 Expenses!A5:J200""),5,1),"""")"),"") | B45: =IFERROR(__xludf.DUMMYFUNCTION("IFERROR(IF(INDEX(IMPORTRANGE(""1wF8uimz-gnzzmqfjHb8Ua7fudqcoq5SrFyToq2B2IO0"",""💸 Expenses!A5:J200""),5,2)="""","""",TEXT(INDEX(IMPORTRANGE(""1wF8uimz-gnzzmqfjHb8Ua7fudqcoq5SrFyToq2B2IO0"",""💸 Expenses!A5:J200""),5,2),""DD-MM-YYYY"")),"""")"),"") | C45: =IFERROR(__xludf.DUMMYFUNCTION("IFERROR(INDEX(IMPORTRANGE(""1wF8uimz-gnzzmqfjHb8Ua7fudqcoq5SrFyToq2B2IO0"",""💸 Expenses!A5:J200""),5,3),"""")"),"") | D45: =IFERROR(__xludf.DUMMYFUNCTION("IFERROR(INDEX(IMPORTRANGE(""1wF8uimz-gnzzmqfjHb8Ua7fudqcoq5SrFyToq2B2IO0"",""💸 Expenses!A5:J200""),5,4),"""")"),"") | E45: =IFERROR(__xludf.DUMMYFUNCTION("IFERROR(INDEX(IMPORTRANGE(""1wF8uimz-gnzzmqfjHb8Ua7fudqcoq5SrFyToq2B2IO0"",""💸 Expenses!A5:J200""),5,5),"""")"),"") | F45: =IFERROR(__xludf.DUMMYFUNCTION("IFERROR(IFERROR(INDEX(IMPORTRANGE(""1wF8uimz-gnzzmqfjHb8Ua7fudqcoq5SrFyToq2B2IO0"",""💸 Expenses!A5:J200""),5,6)*1,0),0)"),0.0) -> 0 | G45: =IFERROR(__xludf.DUMMYFUNCTION("IFERROR(INDEX(IMPORTRANGE(""1wF8uimz-gnzzmqfjHb8Ua7fudqcoq5SrFyToq2B2IO0"",""💸 Expenses!A5:J200""),5,7),"""")"),"") | H45: =IFERROR(__xludf.DUMMYFUNCTION("IFERROR(INDEX(IMPORTRANGE(""1wF8uimz-gnzzmqfjHb8Ua7fudqcoq5SrFyToq2B2IO0"",""💸 Expenses!A5:J200""),5,8),"""")"),"") | I45: =IFERROR(__xludf.DUMMYFUNCTION("IFERROR(INDEX(IMPORTRANGE(""1wF8uimz-gnzzmqfjHb8Ua7fudqcoq5SrFyToq2B2IO0"",""💸 Expenses!A5:J200""),5,9),"""")"),"") | J45: =IFERROR(__xludf.DUMMYFUNCTION("IFERROR(INDEX(IMPORTRANGE(""1wF8uimz-gnzzmqfjHb8Ua7fudqcoq5SrFyToq2B2IO0"",""💸 Expenses!A5:J200""),5,10),"""")"),"")
...

Sheet ⚙️ CONFIG
A1: ⚙️ SOURCE GOOGLE SHEETS CONFIGURATION
A2: Enter the Google Sheets URL for each year in Column B. IMPORTRANGE reads live data from there automatically.
A4: Year | B4: Google Sheets Source URL | C4: Status | D4: Notes
A5: 2026 | B5: https://docs.google.com/spreadsheets/d/12PgU-zwv8gBrFfxvJpoPIPcxUHWup-vsxMH3HWUigZ8/edit | C5: ✅ Configured | D5: Aadi Festival 2026 | E5: =IFERROR(__xludf.DUMMYFUNCTION("IMPORTRANGE(""1wF8uimz-gnzzmqfjHb8Ua7fudqcoq5SrFyToq2B2IO0"",""A1"")"),"")
A6: 2027 | B6: https://docs.google.com/spreadsheets/d/1wF8uimz-gnzzmqfjHb8Ua7fudqcoq5SrFyToq2B2IO0/edit | C6: ✅ Configured | D6: Aadi Festival 2027 | E6: =IFERROR(__xludf.DUMMYFUNCTION("IMPORTRANGE(""12PgU-zwv8gBrFfxvJpoPIPcxUHWup-vsxMH3HWUigZ8"",""A1"")"),"")
A9: 📋 SETUP INSTRUCTIONS (ONE TIME ONLY)
A10: 1. The source Google Sheet must be SHARED with you (or made public).
A11: 2. In Column B above, confirm/update the Google Sheets URL for each year.
A12: 3. Upload this file to Google Drive → File → Import → Open as Google Sheets.
A13: 4. Go to Extensions → Apps Script → paste fix_formulas.gs → Run fixAllFormulas().
A14: 5. Click 'Allow Access' when prompted for IMPORTRANGE permission.
A15: 6. Wait 30 seconds — all data loads automatically from the source tracker.

Sheet ℹ️ HOW TO USE
A1: 🕉 HOW TO USE — GOOGLE SHEETS MASTER TRACKER 🕉
A3: 🚀 FIRST-TIME SETUP (ONE TIME ONLY)
B4: 1. Upload this file to Google Drive → right-click → Open with → Google Sheets.
B5: 2. Go to Extensions → Apps Script → paste the fix_formulas.gs script.
B6: 3. Run fixAllFormulas() — this sets all IMPORTRANGE formulas correctly.
B7: 4. Click 'Allow Access' when the prompt appears.
B8: 5. Wait 10–30 seconds. All data loads automatically from the source tracker.
A10: 📊 WHAT EACH SHEET CONTAINS
B11: 📊 DASHBOARD — Live summary for the selected year. Financial KPIs, category breakdown,
B12: expense type summary, donation type summary, and payment status.
B13: 📈 CUMULATIVE — Year-over-year comparison table and chart. Expense type cross-year view.
B14: 2026 / 2027 — Full detail per year: category breakdown, expense type summary,
B15: expense log (30 rows), donation type summary, donor list (50 rows),
B16: in-kind donations (20 rows).
B17: ⚙️ CONFIG — Source Google Sheets URLs for each year.
A19: 🗂️ EXPENSE TYPES vs CATEGORIES
B20: Expense TYPE = the event/project: Aadi Festival, Temple Development, Temple Operations, Others.
B21: Expense CATEGORY = what was spent on: Puja & Rituals, Food & Catering, Materials, Labour, etc.
B22: Temple Development categories (Materials, Labour, Transport, Food) are shaded in blue-white.
A24: 💝 DONATION TYPES
B25: Donation TYPE = the occasion: Aadi Festival, Temple Development, Birthday Pooja,
B26: Anniversary Pooja, Pournami Pooja, Amavasai Pooja, Weekly Pooja, Others.
B27: The Type and Person Name columns in the donor list show this detail per donor.
A29: ❗ TROUBLESHOOTING
B30: Cells show 0 → Run fixAllFormulas() in Apps Script after uploading to Google Sheets.
B31: Cells show #REF! → IMPORTRANGE not authorized. Run authorizeImportRange() first.
B32: Dates show numbers → The fix_formulas.gs script handles date formatting automatically.
B33: Wrong category → Category name in source must match exactly (e.g. 'Puja & Rituals').
